2022-03-15 22:25:58 ERROR 400 response executing GraphQL.
2022-03-15 22:25:58 ERROR {"errors":[{"message":"Invalid sweep config: invalid hyperparameter configuration: learning","path":["upsertSweep"]}],"data":{"upsertSweep":null}}
2022-03-15 22:25:58 ERROR Traceback (most recent call last):
  File "c:\users\nicol\anaconda3\lib\site-packages\wandb\sdk\lib\retry.py", line 102, in __call__
    result = self._call_fn(*args, **kwargs)
  File "c:\users\nicol\anaconda3\lib\site-packages\wandb\sdk\internal\internal_api.py", line 146, in execute
    six.reraise(*sys.exc_info())
  File "c:\users\nicol\anaconda3\lib\site-packages\six.py", line 703, in reraise
    raise value
  File "c:\users\nicol\anaconda3\lib\site-packages\wandb\sdk\internal\internal_api.py", line 140, in execute
    return self.client.execute(*args, **kwargs)
  File "c:\users\nicol\anaconda3\lib\site-packages\wandb\vendor\gql-0.2.0\gql\client.py", line 52, in execute
    result = self._get_result(document, *args, **kwargs)
  File "c:\users\nicol\anaconda3\lib\site-packages\wandb\vendor\gql-0.2.0\gql\client.py", line 60, in _get_result
    return self.transport.execute(document, *args, **kwargs)
  File "c:\users\nicol\anaconda3\lib\site-packages\wandb\vendor\gql-0.2.0\gql\transport\requests.py", line 39, in execute
    request.raise_for_status()
  File "c:\users\nicol\anaconda3\lib\site-packages\requests\models.py", line 943, in raise_for_status
    raise HTTPError(http_error_msg, response=self)
requests.exceptions.HTTPError: 400 Client Error: Bad Request for url: https://api.wandb.ai/graphql

During handling of the above exception, another exception occurred:

Traceback (most recent call last):
  File "c:\users\nicol\anaconda3\lib\site-packages\wandb\apis\normalize.py", line 24, in wrapper
    return func(*args, **kwargs)
  File "c:\users\nicol\anaconda3\lib\site-packages\wandb\sdk\internal\internal_api.py", line 1892, in upsert_sweep
    raise (e)
  File "c:\users\nicol\anaconda3\lib\site-packages\wandb\sdk\internal\internal_api.py", line 1878, in upsert_sweep
    response = self.gql(
  File "c:\users\nicol\anaconda3\lib\site-packages\wandb\sdk\lib\retry.py", line 118, in __call__
    if not check_retry_fn(e):
  File "c:\users\nicol\anaconda3\lib\site-packages\wandb\sdk\internal\internal_api.py", line 1869, in no_retry_4xx
    raise UsageError(body["errors"][0]["message"])
wandb.errors.UsageError: Invalid sweep config: invalid hyperparameter configuration: learning

During handling of the above exception, another exception occurred:

Traceback (most recent call last):
  File "c:\users\nicol\anaconda3\lib\site-packages\wandb\cli\cli.py", line 86, in wrapper
    return func(*args, **kwargs)
  File "c:\users\nicol\anaconda3\lib\site-packages\wandb\cli\cli.py", line 857, in sweep
    sweep_id, warnings = api.upsert_sweep(
  File "c:\users\nicol\anaconda3\lib\site-packages\wandb\apis\internal.py", line 99, in upsert_sweep
    return self.api.upsert_sweep(*args, **kwargs)
  File "c:\users\nicol\anaconda3\lib\site-packages\wandb\apis\normalize.py", line 62, in wrapper
    six.reraise(CommError, CommError(message, err), sys.exc_info()[2])
  File "c:\users\nicol\anaconda3\lib\site-packages\six.py", line 702, in reraise
    raise value.with_traceback(tb)
  File "c:\users\nicol\anaconda3\lib\site-packages\wandb\apis\normalize.py", line 24, in wrapper
    return func(*args, **kwargs)
  File "c:\users\nicol\anaconda3\lib\site-packages\wandb\sdk\internal\internal_api.py", line 1892, in upsert_sweep
    raise (e)
  File "c:\users\nicol\anaconda3\lib\site-packages\wandb\sdk\internal\internal_api.py", line 1878, in upsert_sweep
    response = self.gql(
  File "c:\users\nicol\anaconda3\lib\site-packages\wandb\sdk\lib\retry.py", line 118, in __call__
    if not check_retry_fn(e):
  File "c:\users\nicol\anaconda3\lib\site-packages\wandb\sdk\internal\internal_api.py", line 1869, in no_retry_4xx
    raise UsageError(body["errors"][0]["message"])
wandb.errors.CommError: Invalid sweep config: invalid hyperparameter configuration: learning

